[2025-01-04T11:17:55.224+0000] {local_task_job_runner.py:123} INFO - ::group::Pre task execution logs
[2025-01-04T11:17:55.239+0000] {taskinstance.py:2613} INFO - Dependencies all met for dep_context=non-requeueable deps ti=<TaskInstance: ml_pipeline.fetch_data_from_postgres manual__2025-01-04T11:17:51.752036+00:00 [queued]>
[2025-01-04T11:17:55.249+0000] {taskinstance.py:2613} INFO - Dependencies all met for dep_context=requeueable deps ti=<TaskInstance: ml_pipeline.fetch_data_from_postgres manual__2025-01-04T11:17:51.752036+00:00 [queued]>
[2025-01-04T11:17:55.250+0000] {taskinstance.py:2866} INFO - Starting attempt 1 of 2
[2025-01-04T11:17:55.416+0000] {taskinstance.py:2889} INFO - Executing <Task(PythonOperator): fetch_data_from_postgres> on 2025-01-04 11:17:51.752036+00:00
[2025-01-04T11:17:55.421+0000] {warnings.py:112} WARNING - /home/***/.local/lib/python3.12/site-packages/***/task/task_runner/standard_task_runner.py:70: DeprecationWarning: This process (pid=82) is multi-threaded, use of fork() may lead to deadlocks in the child.
  pid = os.fork()

[2025-01-04T11:17:55.423+0000] {standard_task_runner.py:72} INFO - Started process 84 to run task
[2025-01-04T11:17:55.423+0000] {standard_task_runner.py:104} INFO - Running: ['***', 'tasks', 'run', 'ml_pipeline', 'fetch_data_from_postgres', 'manual__2025-01-04T11:17:51.752036+00:00', '--job-id', '51', '--raw', '--subdir', 'DAGS_FOLDER/ml_pipeline_dag.py', '--cfg-path', '/tmp/tmpcnkub0b5']
[2025-01-04T11:17:55.424+0000] {standard_task_runner.py:105} INFO - Job 51: Subtask fetch_data_from_postgres
[2025-01-04T11:17:55.465+0000] {task_command.py:467} INFO - Running <TaskInstance: ml_pipeline.fetch_data_from_postgres manual__2025-01-04T11:17:51.752036+00:00 [running]> on host 892a9d4654ee
[2025-01-04T11:17:55.543+0000] {taskinstance.py:3132} INFO - Exporting env vars: AIRFLOW_CTX_DAG_OWNER='***' AIRFLOW_CTX_DAG_ID='ml_pipeline' AIRFLOW_CTX_TASK_ID='fetch_data_from_postgres' AIRFLOW_CTX_EXECUTION_DATE='2025-01-04T11:17:51.752036+00:00' AIRFLOW_CTX_TRY_NUMBER='1' AIRFLOW_CTX_DAG_RUN_ID='manual__2025-01-04T11:17:51.752036+00:00'
[2025-01-04T11:17:55.545+0000] {logging_mixin.py:190} INFO - Task instance is in running state
[2025-01-04T11:17:55.545+0000] {logging_mixin.py:190} INFO -  Previous state of the Task instance: queued
[2025-01-04T11:17:55.545+0000] {logging_mixin.py:190} INFO - Current task name:fetch_data_from_postgres state:running start_date:2025-01-04 11:17:55.240175+00:00
[2025-01-04T11:17:55.546+0000] {logging_mixin.py:190} INFO - Dag name:ml_pipeline and current dag run status:running
[2025-01-04T11:17:55.546+0000] {taskinstance.py:731} INFO - ::endgroup::
[2025-01-04T11:17:55.551+0000] {logging_mixin.py:190} INFO - Data fetched from PostgreSQL:
[2025-01-04T11:17:55.551+0000] {logging_mixin.py:190} INFO - (1, 'Alice', 30, datetime.datetime(2025, 1, 4, 11, 11, 19, 491341))
[2025-01-04T11:17:55.551+0000] {logging_mixin.py:190} INFO - (2, 'Bob', 25, datetime.datetime(2025, 1, 4, 11, 11, 19, 491341))
[2025-01-04T11:17:55.552+0000] {logging_mixin.py:190} INFO - (3, 'Charlie', 35, datetime.datetime(2025, 1, 4, 11, 11, 19, 491341))
[2025-01-04T11:17:55.552+0000] {logging_mixin.py:190} INFO - (4, 'David', 28, datetime.datetime(2025, 1, 4, 11, 12, 1, 121836))
[2025-01-04T11:17:55.552+0000] {logging_mixin.py:190} INFO - (5, 'Eve', 32, datetime.datetime(2025, 1, 4, 11, 12, 1, 121836))
[2025-01-04T11:17:55.552+0000] {logging_mixin.py:190} INFO - (6, 'Frank', 40, datetime.datetime(2025, 1, 4, 11, 12, 1, 121836))
[2025-01-04T11:17:55.553+0000] {logging_mixin.py:190} INFO - (7, 'Grace', 22, datetime.datetime(2025, 1, 4, 11, 12, 1, 121836))
[2025-01-04T11:17:55.553+0000] {logging_mixin.py:190} INFO - (8, 'Hank', 27, datetime.datetime(2025, 1, 4, 11, 12, 1, 121836))
[2025-01-04T11:17:55.554+0000] {taskinstance.py:3311} ERROR - Task failed with exception
Traceback (most recent call last):
  File "/home/airflow/.local/lib/python3.12/site-packages/airflow/models/taskinstance.py", line 767, in _execute_task
    result = _execute_callable(context=context, **execute_callable_kwargs)
             ^^^^^^^^^^^^^^^^^^^^^^^^^^^^^^^^^^^^^^^^^^^^^^^^^^^^^^^^^^^^^
  File "/home/airflow/.local/lib/python3.12/site-packages/airflow/models/taskinstance.py", line 733, in _execute_callable
    return ExecutionCallableRunner(
           ^^^^^^^^^^^^^^^^^^^^^^^^
  File "/home/airflow/.local/lib/python3.12/site-packages/airflow/utils/operator_helpers.py", line 252, in run
    return self.func(*args, **kwargs)
           ^^^^^^^^^^^^^^^^^^^^^^^^^^
  File "/home/airflow/.local/lib/python3.12/site-packages/airflow/models/baseoperator.py", line 422, in wrapper
    return func(self, *args, **kwargs)
           ^^^^^^^^^^^^^^^^^^^^^^^^^^^
  File "/home/airflow/.local/lib/python3.12/site-packages/airflow/operators/python.py", line 238, in execute
    return_value = self.execute_callable()
                   ^^^^^^^^^^^^^^^^^^^^^^^
  File "/home/airflow/.local/lib/python3.12/site-packages/airflow/operators/python.py", line 256, in execute_callable
    return runner.run(*self.op_args, **self.op_kwargs)
           ^^^^^^^^^^^^^^^^^^^^^^^^^^^^^^^^^^^^^^^^^^^
  File "/home/airflow/.local/lib/python3.12/site-packages/airflow/utils/operator_helpers.py", line 252, in run
    return self.func(*args, **kwargs)
           ^^^^^^^^^^^^^^^^^^^^^^^^^^
  File "/opt/airflow/dags/ml_pipeline_dag.py", line 32, in fetch_data_from_postgres
    cur.execute("SELECT AVG(value) FROM sample_data;")
psycopg2.errors.UndefinedColumn: column "value" does not exist
LINE 1: SELECT AVG(value) FROM sample_data;
                   ^

[2025-01-04T11:17:55.566+0000] {logging_mixin.py:190} INFO - Task instance in failure state
[2025-01-04T11:17:55.567+0000] {logging_mixin.py:190} INFO - Task start:2025-01-04 11:17:55.240175+00:00 end:2025-01-04 11:17:55.566481+00:00 duration:0.326306
[2025-01-04T11:17:55.567+0000] {logging_mixin.py:190} INFO - Task:<Task(PythonOperator): fetch_data_from_postgres> dag:<DAG: ml_pipeline> dagrun:<DagRun ml_pipeline @ 2025-01-04 11:17:51.752036+00:00: manual__2025-01-04T11:17:51.752036+00:00, state:running, queued_at: 2025-01-04 11:17:51.764957+00:00. externally triggered: True>
[2025-01-04T11:17:55.568+0000] {logging_mixin.py:190} INFO - Failure caused by column "value" does not exist
LINE 1: SELECT AVG(value) FROM sample_data;
                   ^
[2025-01-04T11:17:55.568+0000] {taskinstance.py:1225} INFO - Marking task as UP_FOR_RETRY. dag_id=ml_pipeline, task_id=fetch_data_from_postgres, run_id=manual__2025-01-04T11:17:51.752036+00:00, execution_date=20250104T111751, start_date=20250104T111755, end_date=20250104T111755
[2025-01-04T11:17:55.582+0000] {taskinstance.py:340} INFO - ::group::Post task execution logs
[2025-01-04T11:17:55.583+0000] {standard_task_runner.py:124} ERROR - Failed to execute job 51 for task fetch_data_from_postgres (column "value" does not exist
LINE 1: SELECT AVG(value) FROM sample_data;
                   ^
; 84)
Traceback (most recent call last):
  File "/home/airflow/.local/lib/python3.12/site-packages/airflow/task/task_runner/standard_task_runner.py", line 117, in _start_by_fork
    ret = args.func(args, dag=self.dag)
          ^^^^^^^^^^^^^^^^^^^^^^^^^^^^^
  File "/home/airflow/.local/lib/python3.12/site-packages/airflow/cli/cli_config.py", line 49, in command
    return func(*args, **kwargs)
           ^^^^^^^^^^^^^^^^^^^^^
  File "/home/airflow/.local/lib/python3.12/site-packages/airflow/utils/cli.py", line 116, in wrapper
    return f(*args, **kwargs)
           ^^^^^^^^^^^^^^^^^^
  File "/home/airflow/.local/lib/python3.12/site-packages/airflow/cli/commands/task_command.py", line 483, in task_run
    task_return_code = _run_task_by_selected_method(args, _dag, ti)
                       ^^^^^^^^^^^^^^^^^^^^^^^^^^^^^^^^^^^^^^^^^^^^
  File "/home/airflow/.local/lib/python3.12/site-packages/airflow/cli/commands/task_command.py", line 256, in _run_task_by_selected_method
    return _run_raw_task(args, ti)
           ^^^^^^^^^^^^^^^^^^^^^^^
  File "/home/airflow/.local/lib/python3.12/site-packages/airflow/cli/commands/task_command.py", line 341, in _run_raw_task
    return ti._run_raw_task(
           ^^^^^^^^^^^^^^^^^
  File "/home/airflow/.local/lib/python3.12/site-packages/airflow/utils/session.py", line 97, in wrapper
    return func(*args, session=session, **kwargs)
           ^^^^^^^^^^^^^^^^^^^^^^^^^^^^^^^^^^^^^^
  File "/home/airflow/.local/lib/python3.12/site-packages/airflow/models/taskinstance.py", line 3005, in _run_raw_task
    return _run_raw_task(
           ^^^^^^^^^^^^^^
  File "/home/airflow/.local/lib/python3.12/site-packages/airflow/models/taskinstance.py", line 273, in _run_raw_task
    TaskInstance._execute_task_with_callbacks(
  File "/home/airflow/.local/lib/python3.12/site-packages/airflow/models/taskinstance.py", line 3159, in _execute_task_with_callbacks
    result = self._execute_task(context, task_orig)
             ^^^^^^^^^^^^^^^^^^^^^^^^^^^^^^^^^^^^^^
  File "/home/airflow/.local/lib/python3.12/site-packages/airflow/models/taskinstance.py", line 3183, in _execute_task
    return _execute_task(self, context, task_orig)
           ^^^^^^^^^^^^^^^^^^^^^^^^^^^^^^^^^^^^^^^
  File "/home/airflow/.local/lib/python3.12/site-packages/airflow/models/taskinstance.py", line 767, in _execute_task
    result = _execute_callable(context=context, **execute_callable_kwargs)
             ^^^^^^^^^^^^^^^^^^^^^^^^^^^^^^^^^^^^^^^^^^^^^^^^^^^^^^^^^^^^^
  File "/home/airflow/.local/lib/python3.12/site-packages/airflow/models/taskinstance.py", line 733, in _execute_callable
    return ExecutionCallableRunner(
           ^^^^^^^^^^^^^^^^^^^^^^^^
  File "/home/airflow/.local/lib/python3.12/site-packages/airflow/utils/operator_helpers.py", line 252, in run
    return self.func(*args, **kwargs)
           ^^^^^^^^^^^^^^^^^^^^^^^^^^
  File "/home/airflow/.local/lib/python3.12/site-packages/airflow/models/baseoperator.py", line 422, in wrapper
    return func(self, *args, **kwargs)
           ^^^^^^^^^^^^^^^^^^^^^^^^^^^
  File "/home/airflow/.local/lib/python3.12/site-packages/airflow/operators/python.py", line 238, in execute
    return_value = self.execute_callable()
                   ^^^^^^^^^^^^^^^^^^^^^^^
  File "/home/airflow/.local/lib/python3.12/site-packages/airflow/operators/python.py", line 256, in execute_callable
    return runner.run(*self.op_args, **self.op_kwargs)
           ^^^^^^^^^^^^^^^^^^^^^^^^^^^^^^^^^^^^^^^^^^^
  File "/home/airflow/.local/lib/python3.12/site-packages/airflow/utils/operator_helpers.py", line 252, in run
    return self.func(*args, **kwargs)
           ^^^^^^^^^^^^^^^^^^^^^^^^^^
  File "/opt/airflow/dags/ml_pipeline_dag.py", line 32, in fetch_data_from_postgres
    cur.execute("SELECT AVG(value) FROM sample_data;")
psycopg2.errors.UndefinedColumn: column "value" does not exist
LINE 1: SELECT AVG(value) FROM sample_data;
                   ^

[2025-01-04T11:17:55.602+0000] {local_task_job_runner.py:266} INFO - Task exited with return code 1
[2025-01-04T11:17:55.621+0000] {taskinstance.py:3895} INFO - 0 downstream tasks scheduled from follow-on schedule check
[2025-01-04T11:17:55.623+0000] {local_task_job_runner.py:245} INFO - ::endgroup::
